Workbook

Sheet 統合ソフト
B3: リリース日 | C3: SOCバージョン | D3: MCUバージョン | E3: Amigoバージョン | F3: 補足 | G3: 顧客
B4: 45170 | C4: =SOC!C4 -> 0.00011 | D4: =MCU!C4 -> 00.01 | E4: PG80530101DATA80530010 | F4: 11
B5: 45225 | C5: =SOC!C5 -> 0.02041 | F5: 22
B6: 45229 | C6: =SOC!C6 -> 0.02046 | F6: 33
B7: 45230 | D7: =MCU!C5 -> 21.00 | F7: 44
B8: 45231 | C8: =SOC!C7 -> 0.02051 | F8: 55
B9: 45236 | D9: =MCU!C6 -> 00.01 | F9: 66
B10: 45244 | C10: =SOC!C8 -> 0.0207 | D10: =MCU!C7 -> 20.49
B11: 45250 | D11: =MCU!C8 -> 20.55
B12: 45264 | D12: =MCU!C9 -> 30.02
B13: 45271 | C13: =SOC!C9 -> 0.03016 | D13: =MCU!C10 -> 30.13 | E13: PG80530201DATA80530020 | F13: Amigo顧客リリース
B14: 45279 | C14: =SOC!C10 -> 0.0303 | D14: =MCU!C11 -> 30.20 | E14: - | F14: 顧客リリース
B15: 45282 | C15: =SOC!C11 -> 0.030331 | F15: 顧客リリース
B16: 45306 | C16: =SOC!C12 -> 0.03066 | D16: =MCU!C12 -> 30.48 | E16: - | F16: HUB対応
B17: 45348 | C17: =SOC!C13 -> 0.03126 | D17: =MCU!C13 -> 30.90 | E17: =Amigo!C6&Amigo!D6 -> PG80530301DATA80530030 | F17: ユーザバージョンアップ対応
B18: 45357 | C18: =SOC!C14 -> 0.031261 | D18: - | E18: -
B19: 45369 | C19: =SOC!C15 -> 0.03156 | D19: =MCU!C14 -> 31.11 | E19: =Amigo!C7&Amigo!D7 -> PG80530401DATA80530040 | F19: セキュアブート対応
B20: 45383 | C20: =SOC!C16 -> 0.0317 | D20: =MCU!C15 -> 31.21 | E20: =Amigo!C7&Amigo!D7 -> PG80530401DATA80530040
B21: 45397 | C21: =SOC!C17 -> 0.0319 | D21: =MCU!C16 -> 31.35 | E21: =Amigo!C9&Amigo!D9 -> PG80530501DATA80530050
B22: 45406 | C22: =SOC!C18 -> 0.03203 | D22: =MCU!C17 -> 31.42 | E22: =E21 -> PG80530501DATA80530050
B23: 45407 | C23: =SOC!C19 -> 0.032031 | D23: =MCU!C17 -> 31.42 | E23: =E22 -> PG80530501DATA80530050
B24: 45411 | C24: =SOC!C20 -> 0.0321 | D24: =MCU!C18 -> 31.50 | E24: =Amigo!C10&Amigo!D10 -> PG80530601DATA80530060
B25: 45432 | C25: =VLOOKUP(B25,SOC!B:D,2,FALSE) -> 0.04 | D25: =VLOOKUP(B25,MCU!B:D,2,FALSE) -> 40.01 | E25: =(VLOOKUP(B25,Amigo!B:E,2,FALSE))&(VLOOKUP(B25,Amigo!B:E,3,FALSE)) -> ↑と同様↑と同様
B26: 45446 | C26: =VLOOKUP(B26,SOC!B:D,2,FALSE) -> 0.0402 | D26: =VLOOKUP(B26,MCU!B:D,2,FALSE) -> 40.18 | E26: =(VLOOKUP(B26,Amigo!B:E,2,FALSE))&(VLOOKUP(B26,Amigo!B:E,3,FALSE)) -> ↑と同様↑と同様
B27: 45460 | C27: =VLOOKUP(B27,SOC!B:D,2,FALSE) -> 0.0404 | D27: =VLOOKUP(B27,MCU!B:D,2,FALSE) -> 40.28 | E27: =(VLOOKUP(B27,Amigo!B:E,2,FALSE))&(VLOOKUP(B27,Amigo!B:E,3,FALSE)) -> PG80530701DATA80530070
B28: 45474 | C28: =VLOOKUP(B28,SOC!B:D,2,FALSE) -> 0.0406 | D28: =VLOOKUP(B28,MCU!B:D,2,FALSE) -> 40.42 | E28: =(VLOOKUP(B28,Amigo!B:E,2,FALSE))&(VLOOKUP(B28,Amigo!B:E,3,FALSE)) -> ↑と同様↑と同様
B29: 45488 | C29: =VLOOKUP(B29,SOC!B:D,2,FALSE) -> 0.0408 | D29: =VLOOKUP(B29,MCU!B:D,2,FALSE) -> 40.56 | E29: =(VLOOKUP(B29,Amigo!B:E,2,FALSE))&(VLOOKUP(B29,Amigo!B:E,3,FALSE)) -> PG80530801DATA80530080
B30: 45492 | C30: =VLOOKUP(B30,SOC!B:D,2,FALSE) -> ↑と同様 | D30: =VLOOKUP(B30,MCU!B:D,2,FALSE) -> ↑と同様 | E30: =(VLOOKUP(B30,Amigo!B:E,2,FALSE))&(VLOOKUP(B30,Amigo!B:E,3,FALSE)) -> PG80530901DATA80530090
B31: 45502 | C31: =VLOOKUP(B31,SOC!B:D,2,FALSE) -> 0.041 | D31: =VLOOKUP(B31,MCU!B:D,2,FALSE) -> 40.71 | E31: =(VLOOKUP(B31,Amigo!B:E,2,FALSE))&(VLOOKUP(B31,Amigo!B:E,3,FALSE)) -> ↑と同様↑と同様
B32: 45510 | C32: =VLOOKUP(B32,SOC!B:D,2,FALSE) -> 0.0411 | D32: =VLOOKUP(B32,MCU!B:D,2,FALSE) -> ↑と同様 | E32: =(VLOOKUP(B32,Amigo!B:E,2,FALSE))&(VLOOKUP(B32,Amigo!B:E,3,FALSE)) -> ↑と同様↑と同様 | F32: AIO用 | G32: 〇
B33: 45523 | C33: =VLOOKUP(B33,SOC!B:D,2,FALSE) -> 0.0413 | D33: =VLOOKUP(B33,MCU!B:D,2,FALSE) -> 40.91 | E33: =(VLOOKUP(B33,Amigo!B:E,2,FALSE))&(VLOOKUP(B33,Amigo!B:E,3,FALSE)) -> PG80530A01DATA805300A0
B34: 45534 | C34: =VLOOKUP(B34,SOC!B:D,2,FALSE) -> 0.0411 | D34: =VLOOKUP(B34,MCU!B:D,2,FALSE) -> 40.72 | E34: =E30 -> PG80530901DATA80530090
B35: 45537 | C35: =VLOOKUP(B35,SOC!B:D,2,FALSE) -> 0.0415 | D35: =VLOOKUP(B35,MCU!B:D,2,FALSE) -> 41.05 | E35: =Amigo!C21&Amigo!D21 -> PG80530B01DATA805300B0
B36: 45553 | C36: =VLOOKUP(B36,SOC!B:D,2,FALSE) -> 0.0417 | D36: =VLOOKUP(B36,MCU!B:D,2,FALSE) -> 41.19 | E36: =Amigo!C22&Amigo!D22 -> PG80530C01DATA805300C0
B37: 2024/9/18_2 | C37: =VLOOKUP(B37,SOC!B:D,2,FALSE) -> 0.04171 | D37: =VLOOKUP(B37,MCU!B:D,2,FALSE) -> 41.19 | E37: =Amigo!C22&Amigo!D22 -> PG80530C01DATA805300C0
B38: 45554 | C38: =VLOOKUP(B38,SOC!B:D,2,FALSE) -> 0.0417 | D38: =VLOOKUP(B38,MCU!B:D,2,FALSE) -> 41.20 | E38: -
B39: 45555 | C39: =VLOOKUP(B39,SOC!B:D,2,FALSE) -> 0.0411 | D39: =VLOOKUP(B39,MCU!B:D,2,FALSE) -> 40.73 | E39: PG80530901DATA80530090 | F39: AIO巻き替え用 | G39: 〇
B40: 45564 | C40: =VLOOKUP(B40,SOC!B:D,2,FALSE) -> 0.0419 | D40: =VLOOKUP(B40,MCU!B:D,2,FALSE) -> 41.36 | E40: =(VLOOKUP(B40,Amigo!B:E,2,FALSE))&(VLOOKUP(B40,Amigo!B:E,3,FALSE)) -> PG80530D01DATA805300D0 | F40: IOP1st
B41: 45579 | C41: =VLOOKUP(B41,SOC!B:D,2,FALSE) -> 0.0421 | D41: =VLOOKUP(B41,MCU!B:D,2,FALSE) -> 41.48 | E41: PG80530D01DATA805300D0
B42: 45593 | C42: =VLOOKUP(B42,SOC!B:D,2,FALSE) -> 0.05 | D42: =VLOOKUP(B42,MCU!B:D,2,FALSE) -> 41.62 | E42: =(VLOOKUP(B42,Amigo!B:E,2,FALSE))&(VLOOKUP(B42,Amigo!B:E,3,FALSE)) -> PG80530E01DATA805300E0 | F42: PP0事前/AIO指摘対応1st
...

Sheet SOC
B3: リリース日 | C3: バージョン | D3: 変更点概要
B4: =統合ソフト!B4 -> 45170 | C4: 0.00011 | D4: 0S対応
B5: 45225 | C5: 0.02041 | D5: Task 109661対応
B6: 45229 | C6: 0.02046 | D6: WiFi設定をデフォルトOffにする
B7: 45231 | C7: 0.02051 | D7: TestMode黒画問題Fix
B8: 45244 | C8: 0.0207 | D8: Change Request 134787 1S初回リリース
B9: 45271 | C9: 0.03016 | D9: Task 141792対応
B10: 45279 | C10: 0.0303 | D10: Task 145339
B11: 45282 | C11: 0.030331 | D11: Task 146766対応
B12: 45306 | C12: 0.03066 | D12: Task 151304
B13: 45348 | C13: 0.03126 | D13: Task 165146
B14: 45357 | C14: 0.031261 | D14: Task 168962 Task 168965
B15: 45369 | C15: 0.03156 | D15: Task 171626
B16: 45383 | C16: 0.0317 | D16: Task 175051
... B25: 45488 | C25: 0.0408 | D25: Task 200629
B26: 45492 | C26: ↑と同様
B27: 45502 | C27: 0.041 | D27: Task 205091
B28: 45510 | C28: 0.0411 | D28: Task 168962
B29: 45523 | C29: 0.0413 | D29: Task 207865
B30: 45534 | C30: 0.0411 | D30: Task 213442
B31: 45537 | C31: 0.0415 | D31: Task 212412
B32: 45553 | C32: 0.0417 | D32: Task 214892
B33: 2024/9/18_2 | C33: 0.04171 | D33: Task 214892
B34: 45554 | C34: 0.0417 | D34: Task 214891
B35: 45555 | C35: 0.0411 | D35: Task 217554
B36: 45564 | C36: 0.0419 | D36: Task 217597
B37: 45579 | C37: 0.0421 | D37: Task 220326
B38: 45593 | C38: 0.05 | D38: Task 220327
B39: 45607 | C39: 0.0503 | D39: Task 222670
B40: 45621 | C40: 0.0505 | D40: Task 227711
B41: 45637 | C41: 0.0507 | D41: Task 236863
B42: 45660 | C42: 0.0511 | D42: Task 245617
B43: 45679 | C43: 0.0513 | D43: Task 245609
B44: 45698 | C44: 0.0516 | D44: Task 245613
B45: 45707 | C45: 0.0517 | D45: Task 254519
... B68: 46125 | C68: 1.0024 | D68: Task 348234

Sheet MCU
B3: リリース日 | C3: バージョン | D3: 変更点概要
B4: =統合ソフト!B4 -> 45170 | C4: 00.01 | D4: 0S対応
B5: 45230 | C5: 21.00 | D5: ChangeRequest 122854 ・CANWAKEUP ・DeepStop
B6: 45236 | C6: 00.01 | D6: 1S対応
B7: 45244 | C7: 20.49 | D7: Change Request 134787 1S初回リリース
B8: 45250 | C8: 20.55 | D8: 「NASDA_Timing Chart_Ver.0.05_20231120.xlsx」対応
B9: 45264 | C9: 30.02 | D9: Task 138678 暗電流問題対策
B10: 45271 | C10: 30.13 | D10: Task 141792対応
B11: 45279 | C11: 30.20 | D11: Task 145339対応
B12: 45306 | C12: 30.48 | D12: Task 151304
B13: 45348 | C13: 30.90 | D13: Task 165146
B14: 45369 | C14: 31.11 | D14: Task 171626
B15: 45383 | C15: 31.21 | D15: Task 175051
B16: 45397 | C16: 31.35 | D16: Task 179588
... B23: 45488 | C23: 40.56 | D23: Task 200629
B24: 45492 | C24: ↑と同様
B25: 45502 | C25: 40.71 | D25: Task 205091
B26: 45510 | C26: ↑と同様
B27: 45523 | C27: 40.91 | D27: Task 207865
B28: 45534 | C28: 40.72 | D28: Task 213442
B29: 45537 | C29: 41.05 | D29: Task 212412
B30: 45553 | C30: 41.19 | D30: Task 214892
B31: 2024/9/18_2 | C31: 41.19 | D31: Task 214892
B32: 45554 | C32: 41.20 | D32: Task 214891
B33: 45555 | C33: 40.73 | D33: Task 217554
B34: 45564 | C34: 41.36 | D34: Task 217597
B35: 45579 | C35: 41.48 | D35: Task 220326
B36: 45593 | C36: 41.62 | D36: Task 220327
B37: 45607 | C37: 41.75 | D37: Task 222670
B38: 45621 | C38: 41.90 | D38: Task 227711
B39: 45637 | C39: 42.07 | D39: Task 236863
B40: 45660 | C40: 42.31 | D40: Task 245617
B41: 45679 | C41: 42.45 | D41: Task 245609
B42: 45698 | C42: 42.66 | D42: Task 245613
B43: 45707 | C43: 42.74 | D43: Task 254519
... B66: 46125 | C66: 50.06 | D66: Task 348234

Sheet Amigo
B3: リリース日 | C3: PG | D3: DATA | E3: 変更点概要
B4: 45170 | C4: PG80530101 | D4: DATA80530010 | E4: IIC→UART変更、PORT変更、音源対応 火入れ対応（HIFI無効暫対策+Rear無音暫対策）
B5: 45271 | C5: PG80530201 | D5: DATA80530020 | E5: Radio周波数関連Spec対応 HIFI、SoundEngine無効化対応 Media音源で後席の音が出ない(Rear無音暫対策) 「Redmine#111303 【M7GRT-L】 LevelOffsetの合計が最大値73の場合、対応するレジスタの値が正しくありません」横展開 #63789：BestStationの無効化
B6: 45348 | C6: PG80530301 | D6: DATA80530030 | E6: AudioDSP対応（※MultiLimiter対応無効、DLOUD Flat設定する） AudioDSP変更よりAudioパラメータ変更対応 HDMマイクとMICChange対応 DuckUnDunk新規対応 ラジオのFMアライメント E-Siri向け4chREF新規対応 HF Volume curve変更対応 FlatOnでボリュームが22から上がらず課題対応
B7: 45369 | C7: PG80530401 | D7: DATA80530040 | E7: AudioDSP対応：HFと割込みのlevelIF変更対応 AudioDSP変更よりAudioパラメータ組み込み対応
B8: 45383 | C8: ↑と同様 | D8: ↑と同様
B9: 45392 | C9: PG80530501 | D9: DATA80530050 | E9: [Tuner] RDS AF時、FM周波数自動変更問題 MT一回目「Redmine#124306【NASDA】SYSAMIOG通信変更IIC⇒UART（表ソフト）」 MT一回目「Redmine#124714【NASDA】SYSAMIOG通信変更IIC⇒UART（裏ソフト）」 QAC一回目「Redmine#124306【NASDA】SYSAMIOG通信変更IIC⇒UART（表ソフト）」 QAC一回目「Redmine#124714【NASDA】SYSAMIOG通信変更IIC⇒UART（裏ソフト）」
B10: 45406 | C10: PG80530601 | D10: DATA80530060 | E10: 【NASDA】Radioパラメータ変更 Issue 176691【NASDA】[Tuner]周波数調整失敗問題 【NASDA】[Tuner]SCAN受信中にSeek不可問題 【NASDA】[Tuner]SCAN Seek中のSeek方向が間違っている問題 【NASDA】[Tuner]SCAN Seek中と受信中にManual Up/Down不可問題
B11: 45432 | C11: ↑と同様 | D11: ↑と同様 | E11: ↑と同様
B12: 45446 | C12: ↑と同様 | D12: ↑と同様 | E12: ↑と同様
B13: 45460 | C13: PG80530701 | D13: DATA80530070 | E13: 【NASDA】CarPlay AddendumR8対応_Main 【NASDA】P13C関連Port対応 【NASDA】Carplay Tel Ref 1ch->4ch関する変更 【NASDA】QAC二回目(NO SOFT CHANGE) 【NASDA】MT二回目 【NASDA】QAC三回目(NO SOFT CHANGE) 【NASDA】MT三回目
B14: 45474 | C14: ↑と同様 | D14: ↑と同様 | E14: ↑と同様
B15: 45488 | C15: PG80530801 | D15: DATA80530080 | E15: 【NASDA】PI取得不可状態でのPS表示用の情報は5秒後消去不可 【NASDA】ハードフィートバック ラジオ（AMラジオのレベルIF変更対応） 【NASDA】SpecTableのAMのSEEK感度の変更とprfm_tblの書き込み
B16: 45492 | C16: PG80530901 | D16: DATA80530090 | E16: 【NASDA】Port20~23変更対応 【NASDA】Amigo VerUp問題
B17: 45502 | C17: ↑と同様 | D17: ↑と同様 | E17: ↑と同様
B18: 45510 | C18: ↑と同様 | D18: ↑と同様 | E18: ↑と同様
B19: 45511 | C19: PG80530A01 | D19: DATA805300A0 | E19: 【NASDA】NDS HPF100Hz 削除対応 【NASDA】「【24市販】 起動直後にTDM_CLKが一瞬出力される」横展開
B20: 45523 | C20: PG80530A01 | D20: DATA805300A0 | E20: ↑と同様
... B33: 46048 | C33: PG80531501 | D33: DATA80530150 | E33: H60E FixEQ`対応

Sheet CANLIB
B3: リリース日 | C3: バージョン | D3: 変更点概要
B4: 45230 | C4: 0000 | D4: CANWAKEUP対応
B5: 45271 | C5: 0001 | D5: Speed通知500ms→100ms その他結合時ITバグ修正
B6: 45306 | C6: 0002 | D6: 問題点No.35：EQPIN判定をMCUと合わせて修正 Task# 145239再起動パラメーターを追加
B7: 45343 | C7: 0004 | D7: ウェイクアップタイム変更(160ms→150ms)
B8: 45369 | C8: 0006 | D8: ①ConceptのNG対応 ②Coverity対応 ③MCANバグ対応
B9: 45383 | C9: 0007 | D9: NDFログサイズの対応
B10: 45397 | C10: 0008 | D10: VCAN機能でS1タイマーの修正
B11: 45411 | C11: 0009 | D11: 再帰関数修正
B12: 45432 | C12: 0010 | D12: DCAN受信処理が割込みから2msサイクリックへ移動 外部WDT制御追加(VCAN_STB設定と同じタイミング) アプリケーションノート変更対応(VCAN_TX のSTOP時の設定 "H")
B13: 45446 | C13: 0011 | D13: ACC OFF⇒ON時にMCanのTxノイズ出力の修正(問題リストNo65)
B14: 45460 | C14: ↑同様 | D14: ↑同様
B15: 45474 | C15: 0012 | D15: Coverity指摘対応(can_module_if.hの修正)
... B30: 45777 | C30: 0016 | D30: ・CMF周期送信タイマー修正 ・Tq数の変更
